def function_with_robust_error_handling(a, b):
    try:
        result = a / b
        return result
    except (ZeroDivisionError, TypeError, ValueError) as e:
        print(f"An error occurred: {e}")
        return None
    except Exception as e:
        print(f"An unexpected error occurred: {e}")
        return None

#The improved solution uses a broader except block to catch any errors related to division
#And also include a generic exception block to catch unexpected errors.